# GB0147

## Graph-Break Type
*Short name describing what triggered the graph break*
Unsupported function call

## Context
*Values or code snippet captured at the break point*
call_function {self} {args} {kwargs}

## Explanation
*Why this specific graph break happened*
Dynamo does not know how to trace the function `{self.debug_repr()}`

## Hints
*Suggestions for fixing or working around the break*
- Avoid calling `{self.debug_repr()}` in your code.
- Please report an issue to PyTorch.



[Back to Registry](../index.md)
