---
layout: default
---
# GB0160

## Graph-Break Type
*Short name describing what triggered the graph break*

Unsupported next() call

## Context
*Values or code snippet captured at the break point*

next({self})

## Explanation
*Explanation of why the graph break was triggered*

Dynamo does not know how to trace calling `next()` on variable `{self}`.

## Hints
*Hints on how to resolve the graph break*

- Dynamo has detected that tracing the code will result in an error when running in eager. Please double check that your code doesn't contain a similar error when actually running eager/uncompiled.


## Additional Information

<!-- ADDITIONAL INFORMATION START - Add custom information below this line -->

<!-- ADDITIONAL INFORMATION END -->


[Click here to add Additional Info](https://github.com/pytorch-labs/compile-graph-break-site/edit/main/docs/gb/gb0160.md)

[Back to Registry](../index.html)
